Workbook
Name Slicer_Company: #N/A
Name Slicer_Metric: #N/A
Name Slicer_Metric2: #N/A
Name Slicer_Period: #N/A
Name Slicer_Period1: #N/A
Name Slicer_Year: #N/A
Name Slicer_Year1: #N/A
Name Slicer_Year2: #N/A
Name Slicer_Year3: #N/A

Sheet Profitability Dashboard
AA3: Year | AB3: (All)
AA5: Sum of Value | AB5: Column Labels
AA6: Row Labels | AB6: EBIT Margin | AC6: Net Profit Margin | AD6: ROA | AE6: ROE
AA7: Big W | AB7: 0.04570384 | AC7: 0.02912132 | AD7: 0.06773684 | AE7: 0.11289474
AA8: KMART | AB8: 0.20194383 | AC8: 0.12066398 | AD8: 0.24177562 | AE8: 0.4029594
AA9: Target | AB9: 0.14062634 | AC9: 0.10239045 | AD9: 0.19802187 | AE9: 0.7707005
AA10: The Reject Shop | AB10: 0.06904255 | AC10: 0.02802482 | AD10: 0.04863321 | AE10: 0.13163979
AA12: Metric | AB12: (All)
AA14: Sum of Value | AB14: Column Labels
AA15: Row Labels | AB15: Big W | AC15: KMART | AD15: Target | AE15: The Reject Shop
AA16: 2022 | AB16: 0.13290304 | AC16: 0.23473146 | AD16: 0.3237994 | AE16: 0.09792428
AA17: 2023 | AB17: 0.10699853 | AC17: 0.32493168 | AD17: 0.45377004 | AE17: 0.11856583
AA18: 2024 | AB18: 0.01555517 | AC18: 0.40767969 | AD18: 0.43416972 | AE18: 0.06085026
AA20: Company | AB20: (All)
G22: Sum of Value | H22: Column Labels | AA22: Sum of Value | AB22: Column Labels
H23: 2022 | L23: 2023 | P23: 2024 | AA23: Row Labels | AB23: EBIT Margin | AC23: ROE
G24: Row Labels | H24: EBIT Margin | I24: Net Profit Margin | J24: ROA | K24: ROE | L24: EBIT Margin | M24: Net Profit Margin | N24: ROA | O24: ROE | P24: EBIT Margin | Q24: Net Profit Margin | R24: ROA | S24: ROE | AA24: 2022 | AB24: 0.11358243 | AC24: 0.42298958
G25: Big W | H25: 0.01241255 | I25: 0.01649049 | J25: 0.039 | K25: 0.065 | L25: 0.03030303 | M25: 0.01073059 | N25: 0.02473684 | O25: 0.04122807 | P25: 0.00298826 | Q25: 0.00190024 | R25: 0.004 | S25: 0.00666667 | AA25: 2023 | AB25: 0.18322205 | AC25: 0.51908734
G26: KMART | H26: 0.0433835 | I26: 0.03134796 | J26: 0.06 | K26: 0.1 | L26: 0.07230842 | M26: 0.03979304 | N26: 0.07981132 | O26: 0.1330189 | P26: 0.08625191 | Q26: 0.04952298 | R26: 0.1019643 | S26: 0.1699405 | AA26: 2024 | AB26: 0.16051208 | AC26: 0.47611751
G27: Target | H27: 0.03526393 | I27: 0.02547654 | J27: 0.05245283 | K27: 0.2106061 | L27: 0.05313187 | M27: 0.03852456 | N27: 0.07475251 | O27: 0.2873611 | P27: 0.05223054 | Q27: 0.03838935 | R27: 0.07081653 | S27: 0.2727333
G28: The Reject Shop | H28: 0.02252245 | I28: 0.01002323 | J28: 0.01799512 | K28: 0.04738348 | L28: 0.02747873 | M28: 0.01249088 | N28: 0.02111695 | O28: 0.05747927 | P28: 0.01904137 | Q28: 0.00551071 | R28: 0.00952114 | S28: 0.02677704 | AA28: Year | AB28: (All)
AA30: Sum of Value | AB30: Column Labels
AA31: Row Labels | AB31: Big W | AC31: KMART | AD31: Target | AE31: The Reject Shop
AA32: EBIT Margin | AB32: 0.04570384 | AC32: 0.20194383 | AD32: 0.14062634 | AE32: 0.06904255
AA33: Net Profit Margin | AB33: 0.02912132 | AC33: 0.12066398 | AD33: 0.10239045 | AE33: 0.02802482
AA34: ROA | AB34: 0.06773684 | AC34: 0.24177562 | AD34: 0.19802187 | AE34: 0.04863321
AA35: ROE | AB35: 0.11289474 | AC35: 0.4029594 | AD35: 0.7707005 | AE35: 0.13163979
AA37: Company | AB37: The Reject Shop
AA39: Sum of Value | AB39: Column Labels
AA40: Row Labels | AB40: 2022 | AC40: 2023 | AD40: 2024
AA41: EBIT Margin | AB41: 0.02252245 | AC41: 0.02747873 | AD41: 0.01904137
AA42: Net Profit Margin | AB42: 0.01002323 | AC42: 0.01249088 | AD42: 0.00551071
AA43: ROA | AB43: 0.01799512 | AC43: 0.02111695 | AD43: 0.00952114
AA44: ROE | AB44: 0.04738348 | AC44: 0.05747927 | AD44: 0.02677704

Sheet Liquidity Dashboard
B3: Ratios | C3: 2022 | D3: 2023 | E3: 2024
B4: Current Ratio | C4: 1.340172 | D4: 1.3115589 | E4: 1.2581319
B5: Quick Ratio | C5: 0.61764537 | D5: 0.51363331 | E5: 0.35372549
B6: Cash Flow Liquidity Ratio | C6: 0.74251191 | D6: 0.65352783 | E6: 0.63058206
B30: Recent year's Ratio | C30: Reject Shop | D30: Industry Avg
B31: Current Ratio | C31: 1.2 | D31: 1.5 - 2.5
B32: Quick Ratio | C32: 0.3 | D32: 1 - 1.5
B33: Cash Flow Liquidity Ratio | C33: 0.6 | D33: 0.8 - 1
B34: Quick Ratio | C34: 0.3 | D34: 0.3-1
B35: Cash flow Ratio | C35: 0.6 | D35: around 1

Sheet Efficiency Dashboard
B3: Period | C3: Asset Turnover | D3: Non-Current Asset Turnover | E3: PPE Turnover
B4: 2022 | C4: 1.795051 | D4: 3.209522 | E4: 16.007331
B5: 2023 | C5: 1.678172 | D5: 3.012063 | E5: 16.101165
B6: 2024 | C6: 1.722686 | D6: 3.026682 | E6: 16.442087
B35: Period | C35: Inventory Turnover | D35: Days Inventory
B36: 2022 | C36: 4.395521 | D36: 83
B37: 2023 | C37: 3.976175 | D37: 92
B38: 2024 | C38: 3.628881 | D38: 101

Sheet Solvency Dashboard
A1: Ratio | B1: Year | C1: Value
A2: Interest Cover | B2: 2022 | C2: 0.11351852
A3: Interest Cover | B3: 2023 | C3: 0.13351346
A4: Interest Cover | B4: 2024 | C4: 0.10057125
A9: Ratio | B9: Year | C9: Value | G9: Sum of Value | H9: Ratio | M9: Sum of Value | N9: Ratio
A10: Gearing (D/E) (%) | B10: 2022 | C10: 123.1116 | G10: Year | H10: Interest Cover | I10: Grand Total | M10: Year | N10: Gearing (D/E) (%) | O10: Grand Total
A11: Gearing (D/E) (%) | B11: 2023 | C11: 125.55528 | G11: 2022 | H11: 0.11351852 | I11: 0.11351852 | M11: 2022 | N11: 123.1116 | O11: 123.1116
A12: Gearing (D/E) (%) | B12: 2024 | C12: 138.88396 | G12: 2023 | H12: 0.13351346 | I12: 0.13351346 | M12: 2023 | N12: 125.55528 | O12: 125.55528
G13: 2024 | H13: 0.10057125 | I13: 0.10057125 | M13: 2024 | N13: 138.88396 | O13: 138.88396
G14: Grand Total | H14: 0.34760324 | I14: 0.34760324 | M14: Grand Total | N14: 387.55084 | O14: 387.55084

Sheet Market Performance Dashboard
A3: Sum of Value | B3: Year | H3: Sum of Value | I3: Metric
A4: Metric | B4: 2022 | C4: 2023 | D4: 2024 | E4: Grand Total | H4: Year | I4: EPS | J4: Share Price | K4: Grand Total
A5: Dividend Payout Ratio | B5: 0 | C5: 0.588 | D5: 0.806 | E5: 1.394 | H5: 2022 | I5: 0.206 | J5: 3.23 | K5: 3.436
A6: Dividend per Share | B6: 0 | C6: 0.16 | D6: 0.1 | E6: 0.26 | H6: 2023 | I6: 0.272 | J6: 4.55 | K6: 4.822
A7: Dividend Yield | B7: 0 | C7: 0.0352 | D7: 0.0303 | E7: 0.0655 | H7: 2024 | I7: 0.124 | J7: 3.3 | K7: 3.424
A8: EPS | B8: 0.206 | C8: 0.272 | D8: 0.124 | E8: 0.602 | H8: Grand Total | I8: 0.602 | J8: 11.08 | K8: 11.682
A9: P/E Ratio | B9: 15.679612 | C9: 16.7 | D9: 26.6 | E9: 58.979612
A10: Share Price | B10: 3.23 | C10: 4.55 | D10: 3.3 | E10: 11.08
A11: Grand Total | B11: 19.115612 | C11: 22.3052 | D11: 30.9603 | E11: 72.381112
T35: `

Sheet Market Performance
A1: Year | B1: Metric | C1: Value | F1: Year | G1: Metric | H1: Value
A2: 2022 | B2: Share Price | C2: =Ratios!F24 -> 3.23 | F2: 2022 | G2: Share Price | H2: =Ratios!F24 -> 3.23
A3: 2022 | B3: EPS | C3: 0.206 | F3: 2022 | G3: EPS | H3: 0.206
A4: 2022 | B4: Dividend per Share | C4: =Ratios!F25 -> 0 | F4: 2022 | G4: Dividend per Share | H4: =Ratios!F25 -> 0
A5: 2022 | B5: Dividend Payout Ratio | C5: =Ratios!F27 -> 0 | F5: 2022 | G5: Dividend Payout Ratio | H5: =Ratios!F27 -> 0
A6: 2022 | B6: P/E Ratio | C6: =Ratios!F28 -> 15.679612 | F6: 2022 | G6: P/E Ratio | H6: =Ratios!F28 -> 15.679612
A7: 2022 | B7: Dividend Yield | C7: =Ratios!F29 -> 0 | F7: 2022 | G7: Dividend Yield | H7: =Ratios!F29 -> 0
A8: 2023 | B8: Share Price | C8: 4.55 | F8: 2023 | G8: Share Price | H8: 4.55
A9: 2023 | B9: EPS | C9: 0.272 | F9: 2023 | G9: EPS | H9: 0.272
A10: 2023 | B10: Dividend per Share | C10: 0.16 | F10: 2023 | G10: Dividend per Share | H10: 0.16
A11: 2023 | B11: Dividend Payout Ratio | C11: 0.588 | F11: 2023 | G11: Dividend Payout Ratio | H11: 0.588
A12: 2023 | B12: P/E Ratio | C12: 16.7 | F12: 2023 | G12: P/E Ratio | H12: 16.7
A13: 2023 | B13: Dividend Yield | C13: 0.0352 | F13: 2023 | G13: Dividend Yield | H13: 0.0352
A14: 2024 | B14: Share Price | C14: 3.3 | F14: 2024 | G14: Share Price | H14: 3.3
A15: 2024 | B15: EPS | C15: 0.124 | F15: 2024 | G15: EPS | H15: 0.124
A16: 2024 | B16: Dividend per Share | C16: 0.1 | F16: 2024 | G16: Dividend per Share | H16: 0.1
A17: 2024 | B17: Dividend Payout Ratio | C17: 0.806 | F17: 2024 | G17: Dividend Payout Ratio | H17: 0.806
A18: 2024 | B18: P/E Ratio | C18: 26.6 | F18: 2024 | G18: P/E Ratio | H18: 26.6
A19: 2024 | B19: Dividend Yield | C19: 0.0303 | F19: 2024 | G19: Dividend Yield | H19: 0.0303

Sheet Income Statement
A1: Year | B1: 2022 | D1: 2023 | F1: 2024 | H1: 2021
A3: Revenue from continuing operations
A4: Sales revenue | B4: 788241 | D4: 819340 | F4: 852736 | H4: 778688
A5: Other income | B5: 128 | D5: 6062 | F5: 2507 | H5: 63
B6: =SUM(B4:B5) -> 788369 | D6: =SUM(D4:D5) -> 825402 | F6: =SUM(F4:F5) -> 855243 | H6: =H4+H5 -> 778751
A8: Expenses
A9: Cost of sales | B9: 467789 | D9: 494167 | F9: 511665 | H9: 464212
A10: Store expenses | B10: 260828 | D10: 261204 | F10: 280853 | H10: 259388
A11: Administrative expenses | B11: 41996 | D11: 47350 | F11: 46440 | H11: 36536
B12: =SUM(B9:B11) -> 770613 | D12: =SUM(D9:D11) -> 802721 | F12: =SUM(F9:F11) -> 838958 | H12: =SUM(H9:H11) -> 760136
A13: EBIT | B13: =B6-B12 -> 17756 | D13: =D6-D12 -> 22681 | F13: =F6-F12 -> 16285 | H13: =H6-H12 -> 18615
A15: Finance costs | B15: 6502 | D15: 8050 | F15: 8937 | H15: 6477
A16: Profit before income tax | B16: =B13-B15 -> 11254 | D16: =D13-D15 -> 14631 | F16: =F13-F15 -> 7348 | H16: =H13-H15 -> 12138
A17: Income tax expense | B17: 3352 | D17: 4321 | F17: 2635 | H17: 3819
A18: Net Profit (NPAT) | B18: =B16-B17 -> 7902 | D18: =D16-D17 -> 10310 | F18: =F16-F17 -> 4713 | H18: =H16-H17 -> 8319
A20: Other comprehensive income
A21: Items that may be re-classified to profit or loss
A22: Changes in the fair value of cash flow hedges | B22: 16569 | D22: -6902 | F22: -4563 | H22: 5579
A23: Income tax relating to components of other comprehensive income | B23: -4971 | D23: 2071 | F23: 1369 | H23: -1674
A24: Other comprehensive income for the period, net of tax | B24: =SUM(B22:B23) -> 11598 | D24: =SUM(D22:D23) -> -4831 | F24: =SUM(F22:F23) -> -3194 | H24: =SUM(H22:H23) -> 3905
A25: Total comprehensive income attributable to shareholders of TRS | B25: =SUM(B18,B24) -> 19500 | D25: =SUM(D18,D24) -> 5479 | F25: =SUM(F18,F24) -> 1519 | H25: =H18+H24 -> 12224
A27: Earnings per share (Cents)
A28: Basic earnings per share | B28: 20.6 | D28: 27.2 | F28: 12.4 | H28: 21.7
A29: Diluted earning per share | B29: 20.2 | D29: 26.4 | F29: 12.1 | H29: 21.4
A37: Debt
A38: Interest Expense
A39: Dividends
A40: Shares Outstanding
A41: Share Price

Sheet Balance Sheet
A1: Year | B1: 2022 | D1: 2023 | F1: 2024 | H1: 2021
A3: Current Assets
A4: Cash and cash equivalents | B4: 77469 | D4: 77335 | F4: 49883 | H4: 73046
A5: Inventories | B5: 113014 | D5: 135550 | F5: 146446 | H5: 99834
A6: Tax receivables | B6: 1893 | F6: 2770 | H6: 1315
A7: Derivative financial instruments | B7: 12766 | D7: 5864 | F7: 1302
A8: Other assets | B8: 4481 | D8: 4056 | F8: 3322 | H8: 3231
A9: Total Current Assets | B9: =SUM(B4:B8) -> 209623 | D9: =SUM(D4:D8) -> 222805 | F9: =SUM(F4:F8) -> 203723 | H9: =SUM(H4:H8) -> 177426
A11: Non-current Assets
A12: Property, Plant and Equipment | B12: 51143 | D12: 50631 | F12: 53095 | H12: 47342
A13: Right-of-use assets | B13: 198717 | D13: 205786 | F13: 212773 | H13: 148574
A14: Deferred tax assets | B14: 17712 | D14: 20050 | F14: 21144 | H14: 27701
A15: Total Non-current Assets | B15: =SUM(B12:B14) -> 267572 | D15: =SUM(D12:D14) -> 276467 | F15: =SUM(F12:F14) -> 287012 | H15: =SUM(H12:H14) -> 223617
A17: Total Assets | B17: =SUM(B9,B15) -> 477195 | D17: =SUM(D9,D15) -> 499272 | F17: =SUM(F9,F15) -> 490735 | H17: =SUM(H9,H15) -> 401043
A20: Current Liabilities
A21: Trade and other payables | B21: 56398 | D21: 59765 | F21: 59539 | H21: 46677
A22: Lease liabilities | B22: 78020 | D22: 84305 | F22: 81309 | H22: 77303
A23: Tax liabilities | D23: 3300 | H23: 10766
A24: Provisions | B24: 10437 | D24: 11080 | F24: 11363 | H24: 3802
A25: Other liabilities | B25: 11560 | D25: 11428 | F25: 9714 | H25: 12029
A26: Total Current Liabilities | B26: =SUM(B21:B25) -> 156415 | D26: =SUM(D21:D25) -> 169878 | F26: =SUM(F21:F25) -> 161925 | H26: =SUM(H21:H25) -> 150577
A28: Non-current Liabilities
A29: Lease liabilities | B29: 139645 | D29: 144124 | F29: 154909 | H29: 89823
A30: Provisions | B30: 4332 | D30: 3335 | F30: 3818 | H30: 3912
A31: Total Non-current Liabilities | B31: =SUM(B29:B30) -> 143977 | D31: =SUM(D29:D30) -> 147459 | F31: =SUM(F29:F30) -> 158727 | H31: =SUM(H29:H30) -> 93735
A33: Total Liabilities | B33: =SUM(B26,B31) -> 300392 | D33: =SUM(D26,D31) -> 317337 | F33: =SUM(F26,F31) -> 320652 | H33: =SUM(H26,H31) -> 244312
A35: Net Assets | B35: =B17-B33 -> 176803 | D35: =D17-D33 -> 181935 | F35: =F17-F33 -> 170083
A36: Working Capital (CA-CL) | B36: =B9-B26 -> 53208 | D36: =D9-D26 -> 52927 | F36: =F9-F26 -> 41798 | H36: =H17-H33 -> 156731
A38: Equity
A39: Contributed equity | B39: 70326 | D39: 67598 | F39: 62589 | H39: 70326
A40: Reserves | B40: 16279 | D40: 13829 | F40: 12172 | H40: 4109
A41: Retained profits | B41: 90198 | D41: 100508 | F41: 95322 | H41: 82296
A42: Total Equity | B42: =SUM(B39:B41) -> 176803 | D42: =SUM(D39:D41) -> 181935 | F42: =SUM(F39:F41) -> 170083 | H42: =SUM(H39:H41) -> 156731
A45: Required for calculations
A46: Average Total Assets | B46: =SUM(B17+H17)/2 -> 439119 | D46: =SUM(B17,D17) / 2 -> 488233.5 | F46: =SUM(D17,F17) / 2 -> 495003.5
A47: Average Non-current Assets | B47: =SUM(B15+H15)/2 -> 245594.5 | D47: =SUM(B15,D15) / 2 -> 272019.5 | F47: =SUM(D15,F15) / 2 -> 281739.5
A48: Average PPE | B48: =SUM(B12+H12)/2 -> 49242.5 | D48: =SUM(B12,D12) / 2 -> 50887 | F48: =SUM(D12,F12) / 2 -> 51863
A49: Average Shareholders Equity | B49: =(B42+H42)/2 -> 166767 | D49: =(B42+D42)/2 -> 179369 | F49: =(D42+F42)/2 -> 176009
A70: Debt
A71: Interest Expense
...

Sheet Cash Flows
A1: Year | B1: 2022 | D1: 2023 | F1: 2024
A3: Cash flows from operating activities
A4: Receipts from customers (inclusive of goods and tax) | B4: 867065 | D4: 901274 | F4: 938010
A5: Payments to suppliers and employees (inclusive of goods and services tax) | B5: -745255 | D5: -789302 | F5: -821141
A6: Interest received | B6: 128 | D6: 1842 | F6: 2460
A7: Insurance income received | D7: 4220 | F7: 47
A8: Borrowing costs and facilities fees paid | B8: -96 | D8: -279 | F8: -270
A9: Interest on lease liabilities | B9: -6406 | D9: -7771 | F9: -8667
A10: Income tax received (net of tax paid) | B10: 704 | D10: 1036 | F10: -8332
A11: Net cash inflows from operating activities | B11: =SUM(B4:B10) -> 116140 | D11: =SUM(D4:D10) -> 111020 | F11: =SUM(F4:F10) -> 102107
A13: Cash flows from investing activities
A14: Payments for property, plant and equipment | B14: -16451 | D14: -12126 | F14: -15741
A15: Net cash outflows used in investing activities | B15: =SUM(B14) -> -16451 | D15: =SUM(D14) -> -12126 | F15: =SUM(F14) -> -15741
A17: Cash flows from financing activities
A18: Principal elements of lease payments | B18: -95266 | D18: -96300 | F18: -98910
A19: Payments for shares bought back | D19: -2728 | F19: -5009
A20: Dividends paid | F20: -9899
A21: Net cash outflows used in financing activities | B21: =SUM(B18:B20) -> -95266 | D21: =SUM(D18:D20) -> -99028 | F21: =SUM(F18:F20) -> -113818
A23: Net (decrease) / increase in cash held | B23: 4423 | D23: -134 | F23: -27452
A24: Cash at the beginning of the financial period | B24: 73046 | D24: =B25 -> 77469 | F24: =D25 -> 77335
A25: Cash at the end of the financial period | B25: =SUM(B23:B24) -> 77469 | D25: =SUM(D23:D24) -> 77335 | F25: =SUM(F23:F24) -> 49883

Sheet Ratios
F1: The Reject Shop | L1: KMART | O1: Target | R1: Big W
B2: Financial Metric | C2: Ratio | D2: Formula | F2: 2022 | H2: 2023 | J2: 2024 | L2: 2022 | M2: 2023 | N2: 2024 | O2: 2022 | P2: 2023 | Q2: 2024 | R2: 2022 | S2: 2023 | T2: 2024
B4: Profitablility | C4: EBIT Margin (%) | D4: (EBIT/Revenue) x 100 | F4: ='Income Statement'!$B$13/'Income Statement'!$B$6*100 -> 2.2522448 | H4: ='Income Statement'!$D$13/'Income Statement'!$D$6*100 -> 2.7478732 | J4: ='Income Statement'!$F$13/'Income Statement'!$F$6*100 -> 1.9041372 | L4: =418/9635*100 -> 4.3383498 | M4: =769/10635*100 -> 7.2308416 | N4: =958/11107*100 -> 8.6251913 | O4: =3848/109120*100 -> 3.526393 | P4: =5707/107412*100 -> 5.3131866 | Q4: =5566/106566*100 -> 5.2230543 | R4: =55/4431*100 -> 1.2412548 | S4: =145/4785*100 -> 3.030303 | T4: =14/4685*100 -> 0.29882604
C5: Net Profit Margin (%) | D5: (NPAT/Revenue) x 100 | F5: ='Income Statement'!$B$18/'Income Statement'!$B$6*100 -> 1.0023225 | H5: ='Income Statement'!$D$18/'Income Statement'!$D$6*100 -> 1.2490883 | J5: ='Income Statement'!$F$18/'Income Statement'!$F$6*100 -> 0.55107145 | L5: =300/9570*100 -> 3.1347962 | M5: =423/10630*100 -> 3.9793039 | N5: =571/11530*100 -> 4.9522984 | O5: =2780/109120*100 -> 2.547654 | P5: =4138/107412*100 -> 3.852456 | Q5: =4091/106566*100 -> 3.8389355 | R5: =78/4730*100 -> 1.6490486 | S5: =47/4380*100 -> 1.0730594 | T5: =8/4210*100 -> 0.19002375
C6: ROA (%) | D6: (NPAT/Average Total Assets) x 100 | F6: ='Income Statement'!$B$18/'Balance Sheet'!$B$46*100 -> 1.7995122 | H6: ='Income Statement'!$D$18/'Balance Sheet'!$D$46*100 -> 2.1116945 | J6: ='Income Statement'!$F$18/'Balance Sheet'!$F$46*100 -> 0.95211448 | L6: =300/5000*100 -> 6 | M6: =423/5300*100 -> 7.9811321 | N6: =571/5600*100 -> 10.196429 | O6: =2780/53000*100 -> 5.245283 | P6: =4138/55356*100 -> 7.4752511 | Q6: =4091/57769*100 -> 7.0816528 | R6: =78/2000*100 -> 3.9 | S6: =47/1900*100 -> 2.4736842 | T6: =8/2000*100 -> 0.4
C7: ROE (%) | D7: (NPAT/Average Shareholder's Equity) x 100 | F7: ='Income Statement'!$B$18/'Balance Sheet'!$B$49*100 -> 4.7383475 | H7: ='Income Statement'!$D$18/'Balance Sheet'!$D$49*100 -> 5.7479275 | J7: ='Income Statement'!$F$18/'Balance Sheet'!$F$49*100 -> 2.677704 | L7: =300/(5000*0.6)*100 -> 10 | M7: =423/(5300*0.6)*100 -> 13.301887 | N7: =571/(5600*0.6)*100 -> 16.994048 | O7: =2780/13200*100 -> 21.060606 | P7: =4138/14400*100 -> 28.736111 | Q7: =4091/15000*100 -> 27.273333 | R7: =78/(2000*0.6)*100 -> 6.5 | S7: =47/(1900*0.6)*100 -> 4.122807 | T7: =8/(2000*0.6)*100 -> 0.66666667
B9: Efficiency | C9: Asset Turnover | D9: Sales Revenue / Average Total Assets | F9: =('Income Statement'!B4)/('Balance Sheet'!B46) -> 1.795051 | H9: =('Income Statement'!D4)/('Balance Sheet'!D46) -> 1.6781724 | J9: =('Income Statement'!F4)/('Balance Sheet'!F46) -> 1.7226868
C10: Non-current Asset Turnover | D10: Sales Revenue / Average Non-current Assets | F10: =('Income Statement'!B4)/('Balance Sheet'!B47) -> 3.2095222 | H10: =('Income Statement'!D4)/('Balance Sheet'!D47) -> 3.0120635 | J10: =('Income Statement'!F4)/('Balance Sheet'!F47) -> 3.0266824
C11: PPE Turnover | D11: Sales Revenue / Average PPE *100 | F11: =('Income Statement'!B4)/('Balance Sheet'!B48) -> 16.007331 | H11: =('Income Statement'!D4)/('Balance Sheet'!D48) -> 16.101165 | J11: =('Income Statement'!F4)/('Balance Sheet'!F48) -> 16.442088
C12: Inventory Turnover | D12: Cost of Goods Sold / Average Inventory | F12: =('Income Statement'!B9) / (('Balance Sheet'!H5 + 'Balance Sheet'!B5) / 2) -> 4.3955217 | H12: ='Income Statement'!D9 / (('Balance Sheet'!B5 + 'Balance Sheet'!D5) /2) -> 3.9761752 | J12: ='Income Statement'!F9 / (('Balance Sheet'!D5 + 'Balance Sheet'!F5) / 2) -> 3.6288813
C13: Days Inventory | D13: 365 / Inventory Turnover Ratio | F13: =(365 / Ratios!F12) -> 83.039062 | H13: =365 / H12 -> 91.796761 | J13: =365 / J12 -> 100.58196
C14: Days Payables | D14: Average Accounts Payable / Cost Of Goods Sold x 365 | F14: =((('Balance Sheet'!H21 + 'Balance Sheet'!B21) / 2) / 'Income Statement'!B9) * 365 -> 40.212975 | H14: =((('Balance Sheet'!B21+'Balance Sheet'!D21) / 2) / 'Income Statement'!D9) * 365 -> 42.899966 | J14: =((('Balance Sheet'!D21 + 'Balance Sheet'!F22 ) / 2) / 'Income Statement'!F9) * 365 -> 50.318089
C15: Days Receivables | D15: Average Accounts Receivable / Net Credit Sales x 365 | F15: 0 | H15: 0 | J15: 0
B17: Liquidity | C17: Current Ratio | D17: Current Assets / Current Liabilities | F17: ='Balance Sheet'!B9/'Balance Sheet'!B26 -> 1.340172 | H17: ='Balance Sheet'!D9/'Balance Sheet'!D26 -> 1.3115589 | J17: ='Balance Sheet'!F9/'Balance Sheet'!F26 -> 1.2581319
C18: Quick Ratio | D18: Current Assets-Inventories-Prepaid Expenses / Current Liabilities | F18: =('Balance Sheet'!B9-'Balance Sheet'!B5)/'Balance Sheet'!B26 -> 0.61764537 | H18: =('Balance Sheet'!D9-'Balance Sheet'!D5)/'Balance Sheet'!D26 -> 0.51363331 | J18: =('Balance Sheet'!F9-'Balance Sheet'!F5)/'Balance Sheet'!F26 -> 0.35372549
C19: Cash Flow Liquidity Ratio | D19: Operating Cash Flow / Current Liabilities | F19: ='Cash Flows'!B11/'Balance Sheet'!B26 -> 0.74251191 | H19: ='Cash Flows'!D11/'Balance Sheet'!D26 -> 0.65352783 | J19: ='Cash Flows'!F11/'Balance Sheet'!F26 -> 0.63058206
B21: Solvency | C21: Interest Cover | D21: EBIT/nterest Expense | F21: =SUM('Income Statement'!B13/'Balance Sheet'!B26) -> 0.11351852 | H21: =SUM('Income Statement'!D13/'Balance Sheet'!D26) -> 0.13351346 | J21: =SUM('Income Statement'!F13/'Balance Sheet'!F26) -> 0.10057125
C22: Gearing (D/E) (%) | D22: (Total Debt/Equity)*100 | F22: =SUM(('Balance Sheet'!B22+'Balance Sheet'!B29)/'Balance Sheet'!B42)*100 -> 123.1116 | H22: =SUM(('Balance Sheet'!D29+'Balance Sheet'!D22)/'Balance Sheet'!D42)*100 -> 125.55528 | J22: =SUM(('Balance Sheet'!F29+'Balance Sheet'!F22)/'Balance Sheet'!F42)*100 -> 138.88396
B24: Market-based Performance | C24: Share price (AUD) | D24: Share Prices on dates closest to end of reporting period | F24: 3.23 | H24: 4.55 | J24: 3.3
C25: Dividends per share (Cents) | H25: 16 | J25: 10 | K25: (Cents)
C26: EPS (Cents) | D26: Set by company | F26: ='Income Statement'!B28 -> 20.6 | H26: ='Income Statement'!D28 -> 27.2 | J26: ='Income Statement'!F28 -> 12.4
C27: Dividend payout | D27: Dividends per share / EPS | H27: =(H25/H26) -> 0.58823529 | J27: =(J25/J26) -> 0.80645161
C28: P/E ratio | D28: Share price / EPS | F28: =(F24)/(F26/100) -> 15.679612 | H28: =(H24)/(H26/100) -> 16.727941 | J28: =(J24)/(J26/100) -> 26.612903
C29: Dividend yield | D29: (Dividends per share / Share price) | H29: =H25/(H24*100) -> 0.035164835 | J29: =J25/(J24*100) -> 0.03030303

Sheet Profitability
B1: Company | C1: Year | D1: Metric | E1: Value
B2: The Reject Shop | C2: 2022 | D2: EBIT Margin | E2: 0.02252245
B3: The Reject Shop | C3: 2022 | D3: Net Profit Margin | E3: 0.01002323
B4: The Reject Shop | C4: 2022 | D4: ROA | E4: 0.01799512
B5: The Reject Shop | C5: 2022 | D5: ROE | E5: 0.04738348
B6: KMART | C6: 2022 | D6: EBIT Margin | E6: 0.0433835
B7: KMART | C7: 2022 | D7: Net Profit Margin | E7: 0.03134796
B8: KMART | C8: 2022 | D8: ROA | E8: 0.06
B9: KMART | C9: 2022 | D9: ROE | E9: 0.1
B10: Target | C10: 2022 | D10: EBIT Margin | E10: 0.03526393
B11: Target | C11: 2022 | D11: Net Profit Margin | E11: 0.02547654
B12: Target | C12: 2022 | D12: ROA | E12: 0.05245283
B13: Target | C13: 2022 | D13: ROE | E13: 0.2106061
... B37: The Reject Shop | C37: 2024 | D37: ROE | E37: 0.02677704
B38: KMART | C38: 2024 | D38: EBIT Margin | E38: 0.08625191 | R38: Sum of Value | S38: Column Labels
B39: KMART | C39: 2024 | D39: Net Profit Margin | E39: 0.04952298 | S39: 2022 | W39: 2023 | AA39: 2024
B40: KMART | C40: 2024 | D40: ROA | E40: 0.1019643 | R40: Row Labels | S40: EBIT Margin | T40: Net Profit Margin | U40: ROA | V40: ROE | W40: EBIT Margin | X40: Net Profit Margin | Y40: ROA | Z40: ROE | AA40: EBIT Margin | AB40: Net Profit Margin | AC40: ROA | AD40: ROE
B41: KMART | C41: 2024 | D41: ROE | E41: 0.1699405 | R41: Big W | S41: 0.01241255 | T41: 0.01649049 | U41: 0.039 | V41: 0.065 | W41: 0.03030303 | X41: 0.01073059 | Y41: 0.02473684 | Z41: 0.04122807 | AA41: 0.00298826 | AB41: 0.00190024 | AC41: 0.004 | AD41: 0.00666667
B42: Target | C42: 2024 | D42: EBIT Margin | E42: 0.05223054 | R42: KMART | S42: 0.0433835 | T42: 0.03134796 | U42: 0.06 | V42: 0.1 | W42: 0.07230842 | X42: 0.03979304 | Y42: 0.07981132 | Z42: 0.1330189 | AA42: 0.08625191 | AB42: 0.04952298 | AC42: 0.1019643 | AD42: 0.1699405
B43: Target | C43: 2024 | D43: Net Profit Margin | E43: 0.03838935 | R43: Target | S43: 0.03526393 | T43: 0.02547654 | U43: 0.05245283 | V43: 0.2106061 | W43: 0.05313187 | X43: 0.03852456 | Y43: 0.07475251 | Z43: 0.2873611 | AA43: 0.05223054 | AB43: 0.03838935 | AC43: 0.07081653 | AD43: 0.2727333
B44: Target | C44: 2024 | D44: ROA | E44: 0.07081653 | R44: The Reject Shop | S44: 0.02252245 | T44: 0.01002323 | U44: 0.01799512 | V44: 0.04738348 | W44: 0.02747873 | X44: 0.01249088 | Y44: 0.02111695 | Z44: 0.05747927 | AA44: 0.01904137 | AB44: 0.00551071 | AC44: 0.00952114 | AD44: 0.02677704
B45: Target | C45: 2024 | D45: ROE | E45: 0.2727333
B46: Big W | C46: 2024 | D46: EBIT Margin | E46: 0.00298826
B47: Big W | C47: 2024 | D47: Net Profit Margin | E47: 0.00190024
B48: Big W | C48: 2024 | D48: ROA | E48: 0.004
B49: Big W | C49: 2024 | D49: ROE | E49: 0.00666667
B51: Company | C51: Year | D51: Metric | E51: Value
B52: Industry Avg | C52: 2022 | D52: EBIT Margin | E52: 0.05
B53: Industry Avg | C53: 2023 | D53: EBIT Margin | E53: 0.05
B54: Industry Avg | C54: 2024 | D54: EBIT Margin | E54: 0.05
B55: Industry Avg | C55: 2022 | D55: Net Profit Margin | E55: 0.032
B56: Industry Avg | C56: 2023 | D56: Net Profit Margin | E56: 0.032
B57: Industry Avg | C57: 2024 | D57: Net Profit Margin | E57: 0.032
B58: Industry Avg | C58: 2022 | D58: ROA | E58: 0.047
B59: Industry Avg | C59: 2023 | D59: ROA | E59: 0.047
B60: Industry Avg | C60: 2024 | D60: ROA | E60: 0.047
B61: Industry Avg | C61: 2022 | D61: ROE | E61: 0.091
B62: Industry Avg | C62: 2023 | D62: ROE | E62: 0.091
B63: Industry Avg | C63: 2024 | D63: ROE | E63: 0.091
... B75: The Reject Shop | C75: 2024 | D75: ROE | E75: 0.02677704
